<?xml version="1.0" ?>
<!-- =================================================================================== -->
<!-- |    This document was autogenerated by xacro from robots/meta_hand_franka.urdf.xacro | -->
<!-- |    EDITING THIS FILE BY HAND IS NOT RECOMMENDED                                 | -->
<!-- =================================================================================== -->
<robot name="meta_hand_franka">
  <!-- Name of this panda -->
  <!-- Adapted from https://github.com/simlabrobotics/allegro_hand_ros/blob/master/allegro_hand_description/allegro_hand_description_left.xacro -->
  <!-- ======================== FINGER PARAMS ======================== -->
  <!-- ========================= THUMB PARAMS ========================= -->
  <!-- ========================= LIMITS ========================= -->
  <!-- ============================================================================= -->
  <!-- ============================================================================= -->
  <!-- ============================================================================= -->
  <!-- END THUMB MACRO -->
  <!-- [[END]] THREE FINGER MACRO -->
  <!-- ============================================================================= -->
  <!-- ============================================================================= -->
  <!-- ============================================================================= -->
  <link name="base_link"/>
  <link name="panda_link0">
    <visual>
      <geometry>
        <mesh filename="package://franka_description/meshes/visual/link0.dae"/>
      </geometry>
    </visual>
    <collision>
      <origin rpy="0 1.5707963267948966 0" xyz="-0.075 0 0.06"/>
      <geometry>
        <cylinder length="0.03" radius="0.06"/>
      </geometry>
    </collision>
    <collision>
      <origin rpy="0 0 0" xyz="-0.06 0 0.06"/>
      <geometry>
        <sphere radius="0.06"/>
      </geometry>
    </collision>
    <collision>
      <origin rpy="0 0 0" xyz="-0.09 0 0.06"/>
      <geometry>
        <sphere radius="0.06"/>
      </geometry>
    </collision>
  </link>
  <link name="panda_link1">
    <visual>
      <geometry>
        <mesh filename="package://franka_description/meshes/visual/link1.dae"/>
      </geometry>
    </visual>
    <collision>
      <origin rpy="0 0 0" xyz="0 0 -0.1915"/>
      <geometry>
        <cylinder length="0.2830" radius="0.06"/>
      </geometry>
    </collision>
    <collision>
      <origin rpy="0 0 0" xyz="0 0 -0.333"/>
      <geometry>
        <sphere radius="0.06"/>
      </geometry>
    </collision>
    <collision>
      <origin rpy="0 0 0" xyz="0 0 -0.05"/>
      <geometry>
        <sphere radius="0.06"/>
      </geometry>
    </collision>
  </link>
  <joint name="panda_joint1" type="revolute">
    <safety_controller k_position="100.0" k_velocity="40.0" soft_lower_limit="-2.8973" soft_upper_limit="2.8973"/>
    <origin rpy="0 0 0" xyz="0 0 0.333"/>
    <parent link="panda_link0"/>
    <child link="panda_link1"/>
    <axis xyz="0 0 1"/>
    <limit effort="87" lower="-2.8973" upper="2.8973" velocity="2.1750"/>
  </joint>
  <link name="panda_link2">
    <visual>
      <geometry>
        <mesh filename="package://franka_description/meshes/visual/link2.dae"/>
      </geometry>
    </visual>
    <collision>
      <origin rpy="0 0 0" xyz="0 0 0"/>
      <geometry>
        <cylinder length="0.12" radius="0.06"/>
      </geometry>
    </collision>
    <collision>
      <origin rpy="0 0 0" xyz="0 0 -0.06"/>
      <geometry>
        <sphere radius="0.06"/>
      </geometry>
    </collision>
    <collision>
      <origin rpy="0 0 0" xyz="0 0 0.06"/>
      <geometry>
        <sphere radius="0.06"/>
      </geometry>
    </collision>
  </link>
  <joint name="panda_joint2" type="revolute">
    <safety_controller k_position="100.0" k_velocity="40.0" soft_lower_limit="-1.7628" soft_upper_limit="1.7628"/>
    <origin rpy="-1.5707963267948966 0 0" xyz="0 0 0"/>
    <parent link="panda_link1"/>
    <child link="panda_link2"/>
    <axis xyz="0 0 1"/>
    <limit effort="87" lower="-1.7628" upper="1.7628" velocity="2.1750"/>
  </joint>
  <link name="panda_link3">
    <visual>
      <geometry>
        <mesh filename="package://franka_description/meshes/visual/link3.dae"/>
      </geometry>
    </visual>
    <collision>
      <origin rpy="0 0 0" xyz="0 0 -0.145"/>
      <geometry>
        <cylinder length="0.15" radius="0.06"/>
      </geometry>
    </collision>
    <collision>
      <origin rpy="0 0 0" xyz="0 0 -0.22"/>
      <geometry>
        <sphere radius="0.06"/>
      </geometry>
    </collision>
    <collision>
      <origin rpy="0 0 0" xyz="0 0 -0.07"/>
      <geometry>
        <sphere radius="0.06"/>
      </geometry>
    </collision>
  </link>
  <joint name="panda_joint3" type="revolute">
    <safety_controller k_position="100.0" k_velocity="40.0" soft_lower_limit="-2.8973" soft_upper_limit="2.8973"/>
    <origin rpy="1.5707963267948966 0 0" xyz="0 -0.316 0"/>
    <parent link="panda_link2"/>
    <child link="panda_link3"/>
    <axis xyz="0 0 1"/>
    <limit effort="87" lower="-2.8973" upper="2.8973" velocity="2.1750"/>
  </joint>
  <link name="panda_link4">
    <visual>
      <geometry>
        <mesh filename="package://franka_description/meshes/visual/link4.dae"/>
      </geometry>
    </visual>
    <collision>
      <origin rpy="0 0 0" xyz="0 0 0"/>
      <geometry>
        <cylinder length="0.12" radius="0.06"/>
      </geometry>
    </collision>
    <collision>
      <origin rpy="0 0 0" xyz="0 0 0.06"/>
      <geometry>
        <sphere radius="0.06"/>
      </geometry>
    </collision>
    <collision>
      <origin rpy="0 0 0" xyz="0 0 -0.06"/>
      <geometry>
        <sphere radius="0.06"/>
      </geometry>
    </collision>
  </link>
  <joint name="panda_joint4" type="revolute">
    <safety_controller k_position="100.0" k_velocity="40.0" soft_lower_limit="-3.0718" soft_upper_limit="-0.0698"/>
    <origin rpy="1.5707963267948966 0 0" xyz="0.0825 0 0"/>
    <parent link="panda_link3"/>
    <child link="panda_link4"/>
    <axis xyz="0 0 1"/>
    <limit effort="87" lower="-3.0718" upper="-0.0698" velocity="2.1750"/>
  </joint>
  <link name="panda_link5">
    <visual>
      <geometry>
        <mesh filename="package://franka_description/meshes/visual/link5.dae"/>
      </geometry>
    </visual>
    <collision>
      <origin rpy="0 0 0" xyz="0 0 -0.26"/>
      <geometry>
        <cylinder length="0.1" radius="0.06"/>
      </geometry>
    </collision>
    <collision>
      <origin rpy="0 0 0" xyz="0 0 -0.31"/>
      <geometry>
        <sphere radius="0.06"/>
      </geometry>
    </collision>
    <collision>
      <origin rpy="0 0 0" xyz="0 0 -0.21"/>
      <geometry>
        <sphere radius="0.06"/>
      </geometry>
    </collision>
    <collision>
      <origin rpy="0 0 0" xyz="0 0.08 -0.13"/>
      <geometry>
        <cylinder length="0.14" radius="0.025"/>
      </geometry>
    </collision>
    <collision>
      <origin rpy="0 0 0" xyz="0 0.08 -0.06"/>
      <geometry>
        <sphere radius="0.025"/>
      </geometry>
    </collision>
    <collision>
      <origin rpy="0 0 0" xyz="0 0.08 -0.20"/>
      <geometry>
        <sphere radius="0.025"/>
      </geometry>
    </collision>
  </link>
  <joint name="panda_joint5" type="revolute">
    <safety_controller k_position="100.0" k_velocity="40.0" soft_lower_limit="-2.8973" soft_upper_limit="2.8973"/>
    <origin rpy="-1.5707963267948966 0 0" xyz="-0.0825 0.384 0"/>
    <parent link="panda_link4"/>
    <child link="panda_link5"/>
    <axis xyz="0 0 1"/>
    <limit effort="12" lower="-2.8973" upper="2.8973" velocity="2.6100"/>
  </joint>
  <link name="panda_link6">
    <visual>
      <geometry>
        <mesh filename="package://franka_description/meshes/visual/link6.dae"/>
      </geometry>
    </visual>
    <collision>
      <origin rpy="0 0 0" xyz="0 0 -0.03"/>
      <geometry>
        <cylinder length="0.08" radius="0.05"/>
      </geometry>
    </collision>
    <collision>
      <origin rpy="0 0 0" xyz="0 0 0.01"/>
      <geometry>
        <sphere radius="0.05"/>
      </geometry>
    </collision>
    <collision>
      <origin rpy="0 0 0" xyz="0 0 -0.07"/>
      <geometry>
        <sphere radius="0.05"/>
      </geometry>
    </collision>
  </link>
  <joint name="panda_joint6" type="revolute">
    <safety_controller k_position="100.0" k_velocity="40.0" soft_lower_limit="-0.0175" soft_upper_limit="3.7525"/>
    <origin rpy="1.5707963267948966 0 0" xyz="0 0 0"/>
    <parent link="panda_link5"/>
    <child link="panda_link6"/>
    <axis xyz="0 0 1"/>
    <limit effort="12" lower="-0.0175" upper="3.7525" velocity="2.6100"/>
  </joint>
  <link name="panda_link7">
    <visual>
      <geometry>
        <mesh filename="package://franka_description/meshes/visual/link7.dae"/>
      </geometry>
    </visual>
    <collision>
      <origin rpy="0 0 0" xyz="0 0 0.01"/>
      <geometry>
        <cylinder length="0.14" radius="0.04"/>
      </geometry>
    </collision>
    <collision>
      <origin rpy="0 0 0" xyz="0 0 0.08"/>
      <geometry>
        <sphere radius="0.04"/>
      </geometry>
    </collision>
    <collision>
      <origin rpy="0 0 0" xyz="0 0 -0.06"/>
      <geometry>
        <sphere radius="0.04"/>
      </geometry>
    </collision>
  </link>
  <joint name="panda_joint7" type="revolute">
    <safety_controller k_position="100.0" k_velocity="40.0" soft_lower_limit="-2.8973" soft_upper_limit="2.8973"/>
    <origin rpy="1.5707963267948966 0 0" xyz="0.088 0 0"/>
    <parent link="panda_link6"/>
    <child link="panda_link7"/>
    <axis xyz="0 0 1"/>
    <limit effort="12" lower="-2.8973" upper="2.8973" velocity="2.6100"/>
  </joint>
  <link name="panda_link8">
    <collision>
      <origin rpy="3.141592653589793 1.5707963267948966 1.5707963267948966" xyz="0.0424 0.0424 -0.0250"/>
      <geometry>
        <cylinder length="0.01" radius="0.03"/>
      </geometry>
    </collision>
    <collision>
      <origin rpy="0 0 0" xyz="0.0424 0.0424 -0.02"/>
      <geometry>
        <sphere radius="0.03"/>
      </geometry>
    </collision>
    <collision>
      <origin rpy="0 0 0" xyz="0.0424 0.0424 -0.03"/>
      <geometry>
        <sphere radius="0.03"/>
      </geometry>
    </collision>
  </link>
  <joint name="panda_joint8" type="fixed">
    <origin rpy="0 0 0" xyz="0 0 0.107"/>
    <parent link="panda_link7"/>
    <child link="panda_link8"/>
  </joint>
  <!--0.002298-->
  <!-- BASE -->
  <link name="meta_hand_base_frame">
    <visual>
      <geometry>
        <mesh filename="package://meta_hand_description/meshes/base_link.STL"/>
      </geometry>
      <origin rpy="0 0 0" xyz="0 0 0 "/>
      <material name="black">
        <color rgba="0.2 0.2 0.2 1"/>
      </material>
    </visual>
    <collision>
      <origin rpy="0 0 0" xyz="-0.009300 0 -0.0475"/>
      <geometry>
        <box size="0.0408 0.1130 0.095"/>
      </geometry>
    </collision>
    <inertial>
      <origin rpy="0 0 0" xyz="0 0 0.0475"/>
      <mass value="0.4154"/>
      <inertia ixx="1e-4" ixy="0.0" ixz="0.0" iyy="1e-4" iyz="0.0" izz="1e-4"/>
    </inertial>
  </link>
  <link name="palm_reskin_link">
    <visual>
      <geometry>
        <mesh filename="package://meta_hand_description/meshes/reskin_palm_pad.stl" scale="0.001 0.001 0.004"/>
      </geometry>
      <origin rpy="1.5707963259 0 1.5707963259" xyz="0 0 0 "/>
      <material name="grey">
        <color rgba="0.4 0.4 0.4 1"/>
      </material>
    </visual>
  </link>
  <joint name="palm_reskin_joint" type="fixed">
    <parent link="meta_hand_base_frame"/>
    <child link="palm_reskin_link"/>
    <origin rpy="0 0 0" xyz="0.0175 -0.0457 -0.041"/>
  </joint>
  <!-- [LINK 0, 4, 8] -->
  <link name="allegro_link_0.0">
    <visual>
      <geometry>
        <mesh filename="package://meta_hand_description/meshes/link_0.0.STL"/>
      </geometry>
      <material name="black">
        <color rgba=".2 .2 .2 1"/>
      </material>
    </visual>
    <collision>
      <geometry>
        <box size="0.0196 0.0275 0.0164"/>
      </geometry>
      <origin rpy="0 0 0" xyz="0 0 0.0082"/>
    </collision>
    <inertial>
      <mass value="0.0119"/>
      <origin rpy="0 0 0" xyz="0 0 0"/>
      <inertia ixx="1.01666658333e-06" ixy="0.0" ixz="0.0" iyy="6.47677333333e-07" iyz="0.0" izz="1.01666658333e-06"/>
    </inertial>
  </link>
  <joint name="allegro_joint_0.0" type="revolute">
    <axis xyz="0 0 1"/>
    <limit effort="0.35" lower="-0.47" upper="0.47" velocity="6.283"/>
    <parent link="meta_hand_base_frame"/>
    <child link="allegro_link_0.0"/>
    <origin rpy="-0.08726646254999999 0 0" xyz="0 0.0435 -0.001542"/>
  </joint>
  <!-- [LINK 1, 5, 9] -->
  <link name="allegro_link_1.0">
    <visual>
      <geometry>
        <mesh filename="package://meta_hand_description/meshes/link_1.0.STL"/>
      </geometry>
      <material name="black">
        <color rgba=".2 .2 .2 1"/>
      </material>
    </visual>
    <collision>
      <geometry>
        <box size="0.0196 0.0275 0.054"/>
      </geometry>
      <origin rpy="0 0 0" xyz="0 0 0.027"/>
    </collision>
    <inertial>
      <mass value="0.065"/>
      <origin rpy="0 0 0" xyz="0 0 0"/>
      <inertia ixx="7.95654166667e-05" ixy="1.7199e-05" ixz="8.75875e-06" iyy="2.47088833333e-05" iyz="2.413125e-05" izz="7.95654166667e-05"/>
    </inertial>
  </link>
  <joint name="allegro_joint_1.0" type="revolute">
    <limit effort="0.35" lower="-0.16" upper="1.0899999999999999" velocity="6.283"/>
    <axis xyz="0 1 0"/>
    <parent link="allegro_link_0.0"/>
    <child link="allegro_link_1.0"/>
    <origin xyz="0 0 0.0164"/>
  </joint>
  <!-- [LINK 2, 6, 10]-->
  <link name="allegro_link_2.0">
    <visual>
      <geometry>
        <mesh filename="package://meta_hand_description/meshes/link_2.0.STL"/>
      </geometry>
      <material name="black">
        <color rgba=".2 .2 .2 1"/>
      </material>
    </visual>
    <collision>
      <geometry>
        <box size="0.0196 0.0275 0.0384"/>
      </geometry>
      <origin rpy="0 0 0" xyz="0 0 0.0192"/>
    </collision>
    <inertial>
      <mass value="0.0355"/>
      <origin rpy="0 0 0" xyz="0 0 0"/>
      <inertia ixx="2.63979183333e-05" ixy="6.67968e-06" ixz="4.783625e-06" iyy="1.34948516667e-05" iyz="9.372e-06" izz="2.63979183333e-05"/>
    </inertial>
  </link>
  <joint name="allegro_joint_2.0" type="revolute">
    <axis xyz="0 1 0"/>
    <limit effort="0.35" lower="-0.17400000000000002" upper="0.87" velocity="6.283"/>
    <parent link="allegro_link_1.0"/>
    <child link="allegro_link_2.0"/>
    <origin xyz="0 0 0.054"/>
  </joint>
  <!-- [LINK 3, 7, 11] -->
  <link name="allegro_link_3.0">
    <visual>
      <geometry>
        <mesh filename="package://meta_hand_description/meshes/link_3.0.STL"/>
      </geometry>
      <material name="black">
        <color rgba=".2 .2 .2 1"/>
      </material>
    </visual>
    <collision>
      <geometry>
        <sphere radius="0.0001"/>
      </geometry>
      <origin rpy="0 0 0" xyz="0 0 0.008"/>
    </collision>
    <inertial>
      <mass value="0.0096"/>
      <origin rpy="0 0 0" xyz="0 0 0"/>
      <inertia ixx="4.701248e-06" ixy="1.255968e-06" ixz="1.2936e-06" iyy="3.649312e-06" iyz="1.7622e-06" izz="4.701248e-06"/>
    </inertial>
  </link>
  <joint name="allegro_joint_3.0" type="revolute">
    <axis xyz="0 1 0"/>
    <limit effort="0.35" lower="-0.17" upper="0.8" velocity="6.283"/>
    <parent link="allegro_link_2.0"/>
    <child link="allegro_link_3.0"/>
    <origin xyz="0 0 0.0384"/>
  </joint>
  <!-- [FINGER TIP] -->
  <link name="allegro_link_3.0_tip">
    <visual>
      <geometry>
        <mesh filename="package://meta_hand_description/meshes/digit.dae"/>
      </geometry>
      <material name="white">
        <color rgba=".9 .9 .9 1"/>
      </material>
      <origin rpy="0 0 0" xyz="0 0 -0.012"/>
    </visual>
    <collision>
      <geometry>
        <sphere radius="0.016"/>
      </geometry>
      <origin rpy="0 0 0" xyz="0.0036695246 0.0000277434 0.0004368531"/>
    </collision>
    <inertial>
      <mass value="0.0168"/>
      <origin rpy="0 0 0" xyz="0 0 0"/>
      <inertia ixx="9.68e-07" ixy="0" ixz="0" iyy="9.68e-07" iyz="0" izz="9.68e-07"/>
    </inertial>
  </link>
  <joint name="allegro_joint_3_tip" type="fixed">
    <parent link="allegro_link_3.0"/>
    <child link="allegro_link_3.0_tip"/>
    <origin rpy="0 0 -1.5707963259" xyz="0 0 0.026699999999999998"/>
  </joint>
  <link name="reskin_link_1.0a">
    <visual>
      <geometry>
        <mesh filename="package://meta_hand_description/meshes/reskin_finger_pad.stl" scale="0.001 0.001 0.002"/>
      </geometry>
      <origin rpy="-1.5707963259 0 -1.5707963259" xyz="0 0 0"/>
      <material name="grey">
        <color rgba="0.4 0.4 0.4 1"/>
      </material>
    </visual>
  </link>
  <joint name="reskin_joint_1a" type="fixed">
    <parent link="allegro_link_1.0"/>
    <child link="reskin_link_1.0a"/>
    <origin rpy="0 0 0" xyz="0.0118 0.009 0.022"/>
  </joint>
  <link name="reskin_link_1.0b">
    <visual>
      <geometry>
        <mesh filename="package://meta_hand_description/meshes/reskin_finger_pad.stl" scale="0.001 0.001 0.002"/>
      </geometry>
      <origin rpy="-1.5707963259 0 -1.5707963259" xyz="0 0 0"/>
      <material name="grey">
        <color rgba="0.4 0.4 0.4 1"/>
      </material>
    </visual>
  </link>
  <joint name="reskin_joint_1b" type="fixed">
    <parent link="allegro_link_1.0"/>
    <child link="reskin_link_1.0b"/>
    <origin rpy="0 0 0" xyz="0.0118 0.009 0.053"/>
  </joint>
  <link name="reskin_link_2.0">
    <visual>
      <geometry>
        <mesh filename="package://meta_hand_description/meshes/reskin_finger_pad.stl" scale="0.001 0.001 0.002"/>
      </geometry>
      <origin rpy="-1.5707963259 0 -1.5707963259" xyz="0 0 0"/>
      <material name="grey">
        <color rgba="0.4 0.4 0.4 1"/>
      </material>
    </visual>
  </link>
  <joint name="reskin_joint_2" type="fixed">
    <parent link="allegro_link_2.0"/>
    <child link="reskin_link_2.0"/>
    <origin rpy="0 0 0" xyz="0.0118 0.009 0.0375"/>
  </joint>
  <!-- [LINK 0, 4, 8] -->
  <link name="allegro_link_4.0">
    <visual>
      <geometry>
        <mesh filename="package://meta_hand_description/meshes/link_0.0.STL"/>
      </geometry>
      <material name="black">
        <color rgba=".2 .2 .2 1"/>
      </material>
    </visual>
    <collision>
      <geometry>
        <box size="0.0196 0.0275 0.0164"/>
      </geometry>
      <origin rpy="0 0 0" xyz="0 0 0.0082"/>
    </collision>
    <inertial>
      <mass value="0.0119"/>
      <origin rpy="0 0 0" xyz="0 0 0"/>
      <inertia ixx="1.01666658333e-06" ixy="0.0" ixz="0.0" iyy="6.47677333333e-07" iyz="0.0" izz="1.01666658333e-06"/>
    </inertial>
  </link>
  <joint name="allegro_joint_4.0" type="revolute">
    <axis xyz="0 0 1"/>
    <limit effort="0.35" lower="-0.47" upper="0.47" velocity="6.283"/>
    <parent link="meta_hand_base_frame"/>
    <child link="allegro_link_4.0"/>
    <origin rpy="0.0 0 0" xyz="0 0 0.0007"/>
  </joint>
  <!-- [LINK 1, 5, 9] -->
  <link name="allegro_link_5.0">
    <visual>
      <geometry>
        <mesh filename="package://meta_hand_description/meshes/link_1.0.STL"/>
      </geometry>
      <material name="black">
        <color rgba=".2 .2 .2 1"/>
      </material>
    </visual>
    <collision>
      <geometry>
        <box size="0.0196 0.0275 0.054"/>
      </geometry>
      <origin rpy="0 0 0" xyz="0 0 0.027"/>
    </collision>
    <inertial>
      <mass value="0.065"/>
      <origin rpy="0 0 0" xyz="0 0 0"/>
      <inertia ixx="7.95654166667e-05" ixy="1.7199e-05" ixz="8.75875e-06" iyy="2.47088833333e-05" iyz="2.413125e-05" izz="7.95654166667e-05"/>
    </inertial>
  </link>
  <joint name="allegro_joint_5.0" type="revolute">
    <limit effort="0.35" lower="-0.16" upper="1.0899999999999999" velocity="6.283"/>
    <axis xyz="0 1 0"/>
    <parent link="allegro_link_4.0"/>
    <child link="allegro_link_5.0"/>
    <origin xyz="0 0 0.0164"/>
  </joint>
  <!-- [LINK 2, 6, 10]-->
  <link name="allegro_link_6.0">
    <visual>
      <geometry>
        <mesh filename="package://meta_hand_description/meshes/link_2.0.STL"/>
      </geometry>
      <material name="black">
        <color rgba=".2 .2 .2 1"/>
      </material>
    </visual>
    <collision>
      <geometry>
        <box size="0.0196 0.0275 0.0384"/>
      </geometry>
      <origin rpy="0 0 0" xyz="0 0 0.0192"/>
    </collision>
    <inertial>
      <mass value="0.0355"/>
      <origin rpy="0 0 0" xyz="0 0 0"/>
      <inertia ixx="2.63979183333e-05" ixy="6.67968e-06" ixz="4.783625e-06" iyy="1.34948516667e-05" iyz="9.372e-06" izz="2.63979183333e-05"/>
    </inertial>
  </link>
  <joint name="allegro_joint_6.0" type="revolute">
    <axis xyz="0 1 0"/>
    <limit effort="0.35" lower="-0.17400000000000002" upper="0.87" velocity="6.283"/>
    <parent link="allegro_link_5.0"/>
    <child link="allegro_link_6.0"/>
    <origin xyz="0 0 0.054"/>
  </joint>
  <!-- [LINK 3, 7, 11] -->
  <link name="allegro_link_7.0">
    <visual>
      <geometry>
        <mesh filename="package://meta_hand_description/meshes/link_3.0.STL"/>
      </geometry>
      <material name="black">
        <color rgba=".2 .2 .2 1"/>
      </material>
    </visual>
    <collision>
      <geometry>
        <sphere radius="0.0001"/>
      </geometry>
      <origin rpy="0 0 0" xyz="0 0 0.008"/>
    </collision>
    <inertial>
      <mass value="0.0096"/>
      <origin rpy="0 0 0" xyz="0 0 0"/>
      <inertia ixx="4.701248e-06" ixy="1.255968e-06" ixz="1.2936e-06" iyy="3.649312e-06" iyz="1.7622e-06" izz="4.701248e-06"/>
    </inertial>
  </link>
  <joint name="allegro_joint_7.0" type="revolute">
    <axis xyz="0 1 0"/>
    <limit effort="0.35" lower="-0.17" upper="0.8" velocity="6.283"/>
    <parent link="allegro_link_6.0"/>
    <child link="allegro_link_7.0"/>
    <origin xyz="0 0 0.0384"/>
  </joint>
  <!-- [FINGER TIP] -->
  <link name="allegro_link_7.0_tip">
    <visual>
      <geometry>
        <mesh filename="package://meta_hand_description/meshes/digit.dae"/>
      </geometry>
      <material name="white">
        <color rgba=".9 .9 .9 1"/>
      </material>
      <origin rpy="0 0 0" xyz="0 0 -0.012"/>
    </visual>
    <collision>
      <geometry>
        <sphere radius="0.016"/>
      </geometry>
      <origin rpy="0 0 0" xyz="0.0036695246 0.0000277434 0.0004368531"/>
    </collision>
    <inertial>
      <mass value="0.0168"/>
      <origin rpy="0 0 0" xyz="0 0 0"/>
      <inertia ixx="9.68e-07" ixy="0" ixz="0" iyy="9.68e-07" iyz="0" izz="9.68e-07"/>
    </inertial>
  </link>
  <joint name="allegro_joint_7_tip" type="fixed">
    <parent link="allegro_link_7.0"/>
    <child link="allegro_link_7.0_tip"/>
    <origin rpy="0 0 0" xyz="0 0 0.026699999999999998"/>
  </joint>
  <link name="reskin_link_5.0a">
    <visual>
      <geometry>
        <mesh filename="package://meta_hand_description/meshes/reskin_finger_pad.stl" scale="0.001 0.001 0.002"/>
      </geometry>
      <origin rpy="-1.5707963259 0 -1.5707963259" xyz="0 0 0"/>
      <material name="grey">
        <color rgba="0.4 0.4 0.4 1"/>
      </material>
    </visual>
  </link>
  <joint name="reskin_joint_5a" type="fixed">
    <parent link="allegro_link_5.0"/>
    <child link="reskin_link_5.0a"/>
    <origin rpy="0 0 0" xyz="0.0118 0.009 0.022"/>
  </joint>
  <link name="reskin_link_5.0b">
    <visual>
      <geometry>
        <mesh filename="package://meta_hand_description/meshes/reskin_finger_pad.stl" scale="0.001 0.001 0.002"/>
      </geometry>
      <origin rpy="-1.5707963259 0 -1.5707963259" xyz="0 0 0"/>
      <material name="grey">
        <color rgba="0.4 0.4 0.4 1"/>
      </material>
    </visual>
  </link>
  <joint name="reskin_joint_5b" type="fixed">
    <parent link="allegro_link_5.0"/>
    <child link="reskin_link_5.0b"/>
    <origin rpy="0 0 0" xyz="0.0118 0.009 0.053"/>
  </joint>
  <link name="reskin_link_6.0">
    <visual>
      <geometry>
        <mesh filename="package://meta_hand_description/meshes/reskin_finger_pad.stl" scale="0.001 0.001 0.002"/>
      </geometry>
      <origin rpy="-1.5707963259 0 -1.5707963259" xyz="0 0 0"/>
      <material name="grey">
        <color rgba="0.4 0.4 0.4 1"/>
      </material>
    </visual>
  </link>
  <joint name="reskin_joint_6" type="fixed">
    <parent link="allegro_link_6.0"/>
    <child link="reskin_link_6.0"/>
    <origin rpy="0 0 0" xyz="0.0118 0.009 0.0375"/>
  </joint>
  <!-- [LINK 0, 4, 8] -->
  <link name="allegro_link_8.0">
    <visual>
      <geometry>
        <mesh filename="package://meta_hand_description/meshes/link_0.0.STL"/>
      </geometry>
      <material name="black">
        <color rgba=".2 .2 .2 1"/>
      </material>
    </visual>
    <collision>
      <geometry>
        <box size="0.0196 0.0275 0.0164"/>
      </geometry>
      <origin rpy="0 0 0" xyz="0 0 0.0082"/>
    </collision>
    <inertial>
      <mass value="0.0119"/>
      <origin rpy="0 0 0" xyz="0 0 0"/>
      <inertia ixx="1.01666658333e-06" ixy="0.0" ixz="0.0" iyy="6.47677333333e-07" iyz="0.0" izz="1.01666658333e-06"/>
    </inertial>
  </link>
  <joint name="allegro_joint_8.0" type="revolute">
    <axis xyz="0 0 1"/>
    <limit effort="0.35" lower="-0.47" upper="0.47" velocity="6.283"/>
    <parent link="meta_hand_base_frame"/>
    <child link="allegro_link_8.0"/>
    <origin rpy="0.08726646254999999 0 0" xyz="0 -0.0435 -0.001542"/>
  </joint>
  <!-- [LINK 1, 5, 9] -->
  <link name="allegro_link_9.0">
    <visual>
      <geometry>
        <mesh filename="package://meta_hand_description/meshes/link_1.0.STL"/>
      </geometry>
      <material name="black">
        <color rgba=".2 .2 .2 1"/>
      </material>
    </visual>
    <collision>
      <geometry>
        <box size="0.0196 0.0275 0.054"/>
      </geometry>
      <origin rpy="0 0 0" xyz="0 0 0.027"/>
    </collision>
    <inertial>
      <mass value="0.065"/>
      <origin rpy="0 0 0" xyz="0 0 0"/>
      <inertia ixx="7.95654166667e-05" ixy="1.7199e-05" ixz="8.75875e-06" iyy="2.47088833333e-05" iyz="2.413125e-05" izz="7.95654166667e-05"/>
    </inertial>
  </link>
  <joint name="allegro_joint_9.0" type="revolute">
    <limit effort="0.35" lower="-0.16" upper="1.0899999999999999" velocity="6.283"/>
    <axis xyz="0 1 0"/>
    <parent link="allegro_link_8.0"/>
    <child link="allegro_link_9.0"/>
    <origin xyz="0 0 0.0164"/>
  </joint>
  <!-- [LINK 2, 6, 10]-->
  <link name="allegro_link_10.0">
    <visual>
      <geometry>
        <mesh filename="package://meta_hand_description/meshes/link_2.0.STL"/>
      </geometry>
      <material name="black">
        <color rgba=".2 .2 .2 1"/>
      </material>
    </visual>
    <collision>
      <geometry>
        <box size="0.0196 0.0275 0.0384"/>
      </geometry>
      <origin rpy="0 0 0" xyz="0 0 0.0192"/>
    </collision>
    <inertial>
      <mass value="0.0355"/>
      <origin rpy="0 0 0" xyz="0 0 0"/>
      <inertia ixx="2.63979183333e-05" ixy="6.67968e-06" ixz="4.783625e-06" iyy="1.34948516667e-05" iyz="9.372e-06" izz="2.63979183333e-05"/>
    </inertial>
  </link>
  <joint name="allegro_joint_10.0" type="revolute">
    <axis xyz="0 1 0"/>
    <limit effort="0.35" lower="-0.17400000000000002" upper="0.87" velocity="6.283"/>
    <parent link="allegro_link_9.0"/>
    <child link="allegro_link_10.0"/>
    <origin xyz="0 0 0.054"/>
  </joint>
  <!-- [LINK 3, 7, 11] -->
  <link name="allegro_link_11.0">
    <visual>
      <geometry>
        <mesh filename="package://meta_hand_description/meshes/link_3.0.STL"/>
      </geometry>
      <material name="black">
        <color rgba=".2 .2 .2 1"/>
      </material>
    </visual>
    <collision>
      <geometry>
        <sphere radius="0.0001"/>
      </geometry>
      <origin rpy="0 0 0" xyz="0 0 0.008"/>
    </collision>
    <inertial>
      <mass value="0.0096"/>
      <origin rpy="0 0 0" xyz="0 0 0"/>
      <inertia ixx="4.701248e-06" ixy="1.255968e-06" ixz="1.2936e-06" iyy="3.649312e-06" iyz="1.7622e-06" izz="4.701248e-06"/>
    </inertial>
  </link>
  <joint name="allegro_joint_11.0" type="revolute">
    <axis xyz="0 1 0"/>
    <limit effort="0.35" lower="-0.17" upper="0.8" velocity="6.283"/>
    <parent link="allegro_link_10.0"/>
    <child link="allegro_link_11.0"/>
    <origin xyz="0 0 0.0384"/>
  </joint>
  <!-- [FINGER TIP] -->
  <link name="allegro_link_11.0_tip">
    <visual>
      <geometry>
        <mesh filename="package://meta_hand_description/meshes/digit.dae"/>
      </geometry>
      <material name="white">
        <color rgba=".9 .9 .9 1"/>
      </material>
      <origin rpy="0 0 0" xyz="0 0 -0.012"/>
    </visual>
    <collision>
      <geometry>
        <sphere radius="0.016"/>
      </geometry>
      <origin rpy="0 0 0" xyz="0.0036695246 0.0000277434 0.0004368531"/>
    </collision>
    <inertial>
      <mass value="0.0168"/>
      <origin rpy="0 0 0" xyz="0 0 0"/>
      <inertia ixx="9.68e-07" ixy="0" ixz="0" iyy="9.68e-07" iyz="0" izz="9.68e-07"/>
    </inertial>
  </link>
  <joint name="allegro_joint_11_tip" type="fixed">
    <parent link="allegro_link_11.0"/>
    <child link="allegro_link_11.0_tip"/>
    <origin rpy="0 0 1.5707963259" xyz="0 0 0.026699999999999998"/>
  </joint>
  <link name="reskin_link_9.0a">
    <visual>
      <geometry>
        <mesh filename="package://meta_hand_description/meshes/reskin_finger_pad.stl" scale="0.001 0.001 0.002"/>
      </geometry>
      <origin rpy="-1.5707963259 0 -1.5707963259" xyz="0 0 0"/>
      <material name="grey">
        <color rgba="0.4 0.4 0.4 1"/>
      </material>
    </visual>
  </link>
  <joint name="reskin_joint_9a" type="fixed">
    <parent link="allegro_link_9.0"/>
    <child link="reskin_link_9.0a"/>
    <origin rpy="0 0 0" xyz="0.0118 0.009 0.022"/>
  </joint>
  <link name="reskin_link_9.0b">
    <visual>
      <geometry>
        <mesh filename="package://meta_hand_description/meshes/reskin_finger_pad.stl" scale="0.001 0.001 0.002"/>
      </geometry>
      <origin rpy="-1.5707963259 0 -1.5707963259" xyz="0 0 0"/>
      <material name="grey">
        <color rgba="0.4 0.4 0.4 1"/>
      </material>
    </visual>
  </link>
  <joint name="reskin_joint_9b" type="fixed">
    <parent link="allegro_link_9.0"/>
    <child link="reskin_link_9.0b"/>
    <origin rpy="0 0 0" xyz="0.0118 0.009 0.053"/>
  </joint>
  <link name="reskin_link_10.0">
    <visual>
      <geometry>
        <mesh filename="package://meta_hand_description/meshes/reskin_finger_pad.stl" scale="0.001 0.001 0.002"/>
      </geometry>
      <origin rpy="-1.5707963259 0 -1.5707963259" xyz="0 0 0"/>
      <material name="grey">
        <color rgba="0.4 0.4 0.4 1"/>
      </material>
    </visual>
  </link>
  <joint name="reskin_joint_10" type="fixed">
    <parent link="allegro_link_10.0"/>
    <child link="reskin_link_10.0"/>
    <origin rpy="0 0 0" xyz="0.0118 0.009 0.0375"/>
  </joint>
  <!-- [LINK 12] -->
  <link name="allegro_link_12.0">
    <visual>
      <geometry>
        <mesh filename="package://meta_hand_description/meshes/link_12.0_right.STL"/>
      </geometry>
      <material name="black">
        <color rgba=".2 .2 .2 1"/>
      </material>
    </visual>
    <collision>
      <geometry>
        <box size="0.0358 0.034 0.0455"/>
      </geometry>
      <origin rpy="0 0 0" xyz="-0.0179 0.009 0.0145"/>
    </collision>
    <inertial>
      <mass value="0.0176"/>
      <origin rpy="0 0 0" xyz="0 0 0"/>
      <inertia ixx="1.89273333333e-5" ixy="7.16716e-06" ixz="5.35568e-06" iyy="1.43008213333e-05" iyz="6.8068e-06" izz="1.89273333333e-05"/>
    </inertial>
  </link>
  <joint name="allegro_joint_12.0" type="revolute">
    <axis xyz="-1 0 0"/>
    <limit effort="0.35" lower="0.263" upper="1.396" velocity="6.283"/>
    <parent link="meta_hand_base_frame"/>
    <child link="allegro_link_12.0"/>
    <origin rpy="0 -1.6580627884499999 -1.5707963259" xyz="-0.0182 0.019333 -0.045987"/>
  </joint>
  <!-- [LINK 13] -->
  <link name="allegro_link_13.0">
    <visual>
      <geometry>
        <mesh filename="package://meta_hand_description/meshes/link_13.0.STL"/>
      </geometry>
      <material name="black">
        <color rgba=".2 .2 .2 1"/>
      </material>
    </visual>
    <collision>
      <geometry>
        <box size="0.0196 0.0275 0.0177"/>
      </geometry>
      <origin rpy="0 0 0" xyz="0 0 0.00885"/>
    </collision>
    <inertial>
      <mass value="0.0119"/>
      <origin rpy="0 0 0" xyz="0 0 0"/>
      <inertia ixx="4.24250866667e-06" ixy="1.032087e-06" ixz="1.603525e-06" iyy="4.52362633333e-06" iyz="1.44808125e-06" izz="4.24250866667e-06"/>
    </inertial>
  </link>
  <joint name="allegro_joint_13.0" type="revolute">
    <axis xyz="0 0 1"/>
    <limit effort="0.35" lower="-0.10499999999999998" upper="1.1629999999999998" velocity="6.283"/>
    <parent link="allegro_link_12.0"/>
    <child link="allegro_link_13.0"/>
    <origin xyz="-0.027 0.005 0.0399"/>
  </joint>
  <!-- [LINK 14] -->
  <link name="allegro_link_14.0">
    <visual>
      <geometry>
        <mesh filename="package://meta_hand_description/meshes/link_14.0.STL"/>
      </geometry>
      <material name="black">
        <color rgba=".2 .2 .2 1"/>
      </material>
    </visual>
    <collision>
      <geometry>
        <box size="0.0196 0.0275 0.0514"/>
      </geometry>
      <origin rpy="0 0 0" xyz="0 0 0.0257"/>
    </collision>
    <inertial>
      <mass value="0.038"/>
      <origin rpy="0 0 0" xyz="0 0 0"/>
      <inertia ixx="4.30439933333e-05" ixy="9.57068e-06" ixz="5.1205e-06" iyy="1.44451933333e-05" iyz="1.342825e-05" izz="4.30439933333e-05"/>
    </inertial>
  </link>
  <joint name="allegro_joint_14.0" type="revolute">
    <axis xyz="0 1 0"/>
    <limit effort="0.35" lower="-0.01999999999999999" upper="1.17" velocity="6.238"/>
    <parent link="allegro_link_13.0"/>
    <child link="allegro_link_14.0"/>
    <origin xyz="0 0 0.0177"/>
  </joint>
  <!-- [LINK 15] -->
  <link name="allegro_link_15.0">
    <visual>
      <geometry>
        <mesh filename="package://meta_hand_description/meshes/link_15.0.STL"/>
      </geometry>
      <material name="black">
        <color rgba=".2 .2 .2 1"/>
      </material>
    </visual>
    <collision>
      <geometry>
        <sphere radius="0.0001"/>
      </geometry>
      <origin rpy="0 0 0" xyz="0 0 0.0159"/>
    </collision>
    <inertial>
      <mass value="0.0388"/>
      <origin rpy="0 0 0" xyz="0 0 0"/>
      <inertia ixx="3.29223173333e-05" ixy="8.042076e-06" ixz="5.2283e-06" iyy="1.47493026667e-5" iyz="1.1283525e-5" izz="3.29223173333e-05"/>
    </inertial>
  </link>
  <joint name="allegro_joint_15.0" type="revolute">
    <axis xyz="0 1 0"/>
    <limit effort="0.35" lower="-0.18000000000000002" upper="1.65" velocity="6.238"/>
    <parent link="allegro_link_14.0"/>
    <child link="allegro_link_15.0"/>
    <origin xyz="0 0 0.0514"/>
  </joint>
  <!-- [FINGER TIP] -->
  <link name="allegro_link_15.0_tip">
    <visual>
      <geometry>
        <mesh filename="package://meta_hand_description/meshes/digit.dae"/>
      </geometry>
      <origin rpy="0 0 0" xyz="0 0 -0.01"/>
      <material name="white">
        <color rgba=".9 .9 .9 1"/>
      </material>
    </visual>
    <collision>
      <geometry>
        <sphere radius="0.016"/>
      </geometry>
      <origin rpy="0 0 0" xyz="0.0036695246 0.0000277434 0.0004368531"/>
    </collision>
    <inertial>
      <mass value="0.0168"/>
      <origin rpy="0 0 0" xyz="0 0 0"/>
      <inertia ixx="9.68e-07" ixy="0" ixz="0" iyy="9.68e-07" iyz="0" izz="9.68e-07"/>
    </inertial>
  </link>
  <joint name="allegro_joint_15_tip" type="fixed">
    <parent link="allegro_link_15.0"/>
    <child link="allegro_link_15.0_tip"/>
    <origin rpy="0 0 -1.0471975506" xyz="0 0 0.042300000000000004"/>
  </joint>
  <link name="reskin_link_14.0">
    <visual>
      <geometry>
        <mesh filename="package://meta_hand_description/meshes/reskin_finger_pad.stl" scale="0.001 0.001 0.002"/>
      </geometry>
      <origin rpy="-1.5707963259 0 -1.5707963259" xyz="0 0 0"/>
      <material name="grey">
        <color rgba="0.4 0.4 0.4 1"/>
      </material>
    </visual>
  </link>
  <joint name="reskin_joint_14" type="fixed">
    <parent link="allegro_link_14.0"/>
    <child link="reskin_link_14.0"/>
    <origin rpy="0 0 0" xyz="0.0118 0.009 0.022"/>
  </joint>
  <link name="reskin_link_15.0">
    <visual>
      <geometry>
        <mesh filename="package://meta_hand_description/meshes/reskin_finger_pad.stl" scale="0.001 0.001 0.002"/>
      </geometry>
      <origin rpy="-1.5707963259 0 -1.5707963259" xyz="0 0 0"/>
      <material name="grey">
        <color rgba="0.4 0.4 0.4 1"/>
      </material>
    </visual>
  </link>
  <joint name="reskin_joint_15" type="fixed">
    <parent link="allegro_link_15.0"/>
    <child link="reskin_link_15.0"/>
    <origin rpy="0 0 0" xyz="0.0118 0.009 0.022"/>
  </joint>
  <joint name="base_link_joint" type="fixed">
    <parent link="base_link"/>
    <child link="panda_link0"/>
    <origin rpy="0 0 0" xyz="0 0 0"/>
  </joint>
  <link name="hand_base_link"/>
  <joint name="arm_hand_joint" type="fixed">
    <parent link="panda_link8"/>
    <child link="hand_base_link"/>
    <!--<origin xyz="0.02061 0 0.0407" rpy="0 0 0"/>-->
    <origin rpy="0 0 2.356" xyz="-0.0148 0.0148 0.0407"/>
  </joint>
  <joint name="hand_base_joint" type="fixed">
    <parent link="hand_base_link"/>
    <child link="meta_hand_base_frame"/>
    <origin rpy="0 0 0" xyz="-0.011 0 0.095"/>
  </joint>
  <link name="meta_hand_tool_frame"/>
  <joint name="tool_frame_joint" type="fixed">
    <parent link="meta_hand_base_frame"/>
    <child link="meta_hand_tool_frame"/>
    <origin rpy="0.0 0.0 0.0" xyz="0.0 0.0 0.0"/>
  </joint>
</robot>
